Workbook

Sheet Load Sched
B1: 400V
B3: AMPERE | G3: MULTI | H3: AMPERE TRIP | L3: KW
B4: L1 | C4: L2 | D4: L3 | E4: 3 PHASE | H4: 1 PHASE | I4: 3 PHASE | J4: OVERALL | L4: 1 PHASE | N4: 3 PHASE | P4: OVERALL
A6: 1 | C6: 32.91 | G6: 1.25 | H6: =MAX(B6:D6)*G6 -> 41.1375 | I6: =E6*G6 -> 0 | J6: =IF((H6+I6=0),"-",(MAX(B6:D6)+E6)*G6) -> 41.1375 | L6: =SUM(B6:D6)*0.23 -> 7.5693 | N6: =E6*0.4*1.732 -> 0 | P6: =IF(L6+N6=0,"-",L6+(E6*0.4*1.732)) -> 7.5693
A7: 2 | G7: 1.25 | H7: =MAX(B7:D7)*G7 -> 0 | I7: =E7*G7 -> 0 | J7: =IF((H7+I7=0),"-",(MAX(B7:D7)+E7)*G7) -> - | L7: =SUM(B7:D7)*0.23 -> 0 | N7: =E7*0.4*1.732 -> 0 | P7: =IF(L7+N7=0,"-",L7+(E7*0.4*1.732)) -> -
S8: 1 PHASE | W8: 3 PHASE | Y8: CONNECTED DF
A9: 3 | G9: 1.25 | H9: =MAX(B9:D9)*G9 -> 0 | I9: =E9*G9 -> 0 | J9: =IF((H9+I9=0),"-",(MAX(B9:D9)+E9)*G9) -> - | L9: =SUM(B9:D9)*0.23 -> 0 | N9: =E9*0.4*1.732 -> 0 | P9: =IF(L9+N9=0,"-",L9+(E9*0.4*1.732)) -> - | Z9: 0.8 | AB9: =$S$14*Z9 -> 6.05544
A10: 4 | G10: 1.25 | H10: =MAX(B10:D10)*G10 -> 0 | I10: =E10*G10 -> 0 | J10: =IF((H10+I10=0),"-",(MAX(B10:D10)+E10)*G10) -> - | L10: =SUM(B10:D10)*0.23 -> 0 | N10: =E10*0.4*1.732 -> 0 | P10: =IF(L10+N10=0,"-",L10+(E10*0.4*1.732)) -> - | R10: KVA | S10: =B54*0.23 -> 0 | T10: =C54*0.23 -> 7.5693 | U10: =D54*0.23 -> 0 | W10: =E54*0.4*1.732 -> 0 | Z10: 0.7 | AB10: =$S$14*Z10 -> 5.29851
Z11: 0.6 | AB11: =$S$14*Z11 -> 4.54158
A12: 5 | G12: 1.25 | H12: =MAX(B12:D12)*G12 -> 0 | I12: =E12*G12 -> 0 | J12: =IF((H12+I12=0),"-",(MAX(B12:D12)+E12)*G12) -> - | L12: =SUM(B12:D12)*0.23 -> 0 | N12: =E12*0.4*1.732 -> 0 | P12: =IF(L12+N12=0,"-",L12+(E12*0.4*1.732)) -> - | R12: TOTAL KVA | S12: =SUM(S10:U10) -> 7.5693 | W12: =W10 -> 0 | Z12: 0.52 | AB12: =$S$14*Z12 -> 3.936036
A13: 6 | G13: 1.25 | H13: =MAX(B13:D13)*G13 -> 0 | I13: =E13*G13 -> 0 | J13: =IF((H13+I13=0),"-",(MAX(B13:D13)+E13)*G13) -> - | L13: =SUM(B13:D13)*0.23 -> 0 | N13: =E13*0.4*1.732 -> 0 | P13: =IF(L13+N13=0,"-",L13+(E13*0.4*1.732)) -> - | Z13: 0.48 | AB13: =$S$14*Z13 -> 3.633264
R14: OVERALL KVA | S14: =SUM(S10:U10) +W10 -> 7.5693 | Z14: 0.29 | AB14: =$S$14*Z14 -> 2.195097
A15: 7 | G15: 1.25 | H15: =MAX(B15:D15)*G15 -> 0 | I15: =E15*G15 -> 0 | J15: =IF((H15+I15=0),"-",(MAX(B15:D15)+E15)*G15) -> - | L15: =SUM(B15:D15)*0.23 -> 0 | N15: =E15*0.4*1.732 -> 0 | P15: =IF(L15+N15=0,"-",L15+(E15*0.4*1.732)) -> - | Z15: 0.2 | AB15: =$S$14*Z15 -> 1.51386
A16: 8 | G16: 1.25 | H16: =MAX(B16:D16)*G16 -> 0 | I16: =E16*G16 -> 0 | J16: =IF((H16+I16=0),"-",(MAX(B16:D16)+E16)*G16) -> - | L16: =SUM(B16:D16)*0.23 -> 0 | N16: =E16*0.4*1.732 -> 0 | P16: =IF(L16+N16=0,"-",L16+(E16*0.4*1.732)) -> -
Y17: TEST | Z17: 0.8 | AB17: =AA17*Z17 -> 0
A18: 9 | G18: 1.25 | H18: =MAX(B18:D18)*G18 -> 0 | I18: =E18*G18 -> 0 | J18: =IF((H18+I18=0),"-",(MAX(B18:D18)+E18)*G18) -> - | L18: =SUM(B18:D18)*0.23 -> 0 | N18: =E18*0.4*1.732 -> 0 | P18: =IF(L18+N18=0,"-",L18+(E18*0.4*1.732)) -> - | Z18: 0.7 | AB18: =AA18*Z18 -> 0
A19: 10 | G19: 1.25 | H19: =MAX(B19:D19)*G19 -> 0 | I19: =E19*G19 -> 0 | J19: =IF((H19+I19=0),"-",(MAX(B19:D19)+E19)*G19) -> - | L19: =SUM(B19:D19)*0.23 -> 0 | N19: =E19*0.4*1.732 -> 0 | P19: =IF(L19+N19=0,"-",L19+(E19*0.4*1.732)) -> - | R19: TOTAL AT COMPUTATION | Z19: 0.6 | AB19: =AA19*Z19 -> 0
T20: 1 PHASE | U20: 3 PHASE | Z20: 0.5 | AB20: =AA20*Z20 -> 0
A21: 11 | G21: 1.25 | H21: =MAX(B21:D21)*G21 -> 0 | I21: =E21*G21 -> 0 | J21: =IF((H21+I21=0),"-",(MAX(B21:D21)+E21)*G21) -> - | L21: =SUM(B21:D21)*0.23 -> 0 | N21: =E21*0.4*1.732 -> 0 | P21: =IF(L21+N21=0,"-",L21+(E21*0.4*1.732)) -> - | Z21: 0.4 | AB21: =AA21*Z21 -> 0
A22: 12 | G22: 1.25 | H22: =MAX(B22:D22)*G22 -> 0 | I22: =E22*G22 -> 0 | J22: =IF((H22+I22=0),"-",(MAX(B22:D22)+E22)*G22) -> - | L22: =SUM(B22:D22)*0.23 -> 0 | N22: =E22*0.4*1.732 -> 0 | P22: =IF(L22+N22=0,"-",L22+(E22*0.4*1.732)) -> - | R22: AMPERE | T22: =MAX(B54:D54) -> 32.91 | U22: =E54 -> 0 | Z22: 0.3 | AB22: =AA22*Z22 -> 0
A24: 13 | G24: 1.25 | H24: =MAX(B24:D24)*G24 -> 0 | I24: =E24*G24 -> 0 | J24: =IF((H24+I24=0),"-",(MAX(B24:D24)+E24)*G24) -> - | L24: =SUM(B24:D24)*0.23 -> 0 | N24: =E24*0.4*1.732 -> 0 | P24: =IF(L24+N24=0,"-",L24+(E24*0.4*1.732)) -> - | R24: TOTAL AMPERE | T24: =T22+U22 -> 32.91
A25: 14 | G25: 1.25 | H25: =MAX(B25:D25)*G25 -> 0 | I25: =E25*G25 -> 0 | J25: =IF((H25+I25=0),"-",(MAX(B25:D25)+E25)*G25) -> - | L25: =SUM(B25:D25)*0.23 -> 0 | N25: =E25*0.4*1.732 -> 0 | P25: =IF(L25+N25=0,"-",L25+(E25*0.4*1.732)) -> -
R26: MAINS AT | T26: =T24*1.25 -> 41.1375 | Y26: MAINS AT x DF
A27: 15 | G27: 1.25 | H27: =MAX(B27:D27)*G27 -> 0 | I27: =E27*G27 -> 0 | J27: =IF((H27+I27=0),"-",(MAX(B27:D27)+E27)*G27) -> - | L27: =SUM(B27:D27)*0.23 -> 0 | N27: =E27*0.4*1.732 -> 0 | P27: =IF(L27+N27=0,"-",L27+(E27*0.4*1.732)) -> - | Z27: 0.8 | AB27: =$T$26*Z27 -> 32.91
A28: 16 | G28: 1.25 | H28: =MAX(B28:D28)*G28 -> 0 | I28: =E28*G28 -> 0 | J28: =IF((H28+I28=0),"-",(MAX(B28:D28)+E28)*G28) -> - | L28: =SUM(B28:D28)*0.23 -> 0 | N28: =E28*0.4*1.732 -> 0 | P28: =IF(L28+N28=0,"-",L28+(E28*0.4*1.732)) -> - | Z28: 0.7 | AB28: =$T$26*Z28 -> 28.79625
Z29: 0.6 | AB29: =$T$26*Z29 -> 24.6825
A30: 17 | G30: 1.25 | H30: =MAX(B30:D30)*G30 -> 0 | I30: =E30*G30 -> 0 | J30: =IF((H30+I30=0),"-",(MAX(B30:D30)+E30)*G30) -> - | L30: =SUM(B30:D30)*0.23 -> 0 | N30: =E30*0.4*1.732 -> 0 | P30: =IF(L30+N30=0,"-",L30+(E30*0.4*1.732)) -> - | Z30: 0.48 | AB30: =$T$26*Z30 -> 19.746
A31: 18 | G31: 1.25 | H31: =MAX(B31:D31)*G31 -> 0 | I31: =E31*G31 -> 0 | J31: =IF((H31+I31=0),"-",(MAX(B31:D31)+E31)*G31) -> - | L31: =SUM(B31:D31)*0.23 -> 0 | N31: =E31*0.4*1.732 -> 0 | P31: =IF(L31+N31=0,"-",L31+(E31*0.4*1.732)) -> - | R31: AT COMPUTATION | Z31: 3 | AB31: =$T$26*Z31 -> 123.4125
S32: SAFETY | T32: AMP | U32: AT | Z32: 0.25 | AB32: =$T$26*Z32 -> 10.284375
A33: 19 | G33: 1.25 | H33: =MAX(B33:D33)*G33 -> 0 | I33: =E33*G33 -> 0 | J33: =IF((H33+I33=0),"-",(MAX(B33:D33)+E33)*G33) -> - | L33: =SUM(B33:D33)*0.23 -> 0 | N33: =E33*0.4*1.732 -> 0 | P33: =IF(L33+N33=0,"-",L33+(E33*0.4*1.732)) -> - | Y33: for units | Z33: 0.23 | AB33: =$T$26*Z33 -> 9.461625
A34: 20 | G34: 1.25 | H34: =MAX(B34:D34)*G34 -> 0 | I34: =E34*G34 -> 0 | J34: =IF((H34+I34=0),"-",(MAX(B34:D34)+E34)*G34) -> - | L34: =SUM(B34:D34)*0.23 -> 0 | N34: =E34*0.4*1.732 -> 0 | P34: =IF(L34+N34=0,"-",L34+(E34*0.4*1.732)) -> - | R34: NORMAL LOAD | S34: 1.25 | U34: =T34*S34 -> 0
R35: 1 PHASE ACCU | S35: 2.25 | U35: =T35*S35 -> 0 | Y35: TEST | Z35: 0.8 | AB35: =AA35*Z35*1.25 -> 0
A36: 21 | G36: 1.25 | H36: =MAX(B36:D36)*G36 -> 0 | I36: =E36*G36 -> 0 | J36: =IF((H36+I36=0),"-",(MAX(B36:D36)+E36)*G36) -> - | L36: =SUM(B36:D36)*0.23 -> 0 | N36: =E36*0.4*1.732 -> 0 | P36: =IF(L36+N36=0,"-",L36+(E36*0.4*1.732)) -> - | R36: WATER HEATER | S36: 1.5 | U36: =T36*S36 -> 0 | Z36: 0.7 | AB36: =AA36*Z36*1.25 -> 0
A37: 22 | G37: 1.25 | H37: =MAX(B37:D37)*G37 -> 0 | I37: =E37*G37 -> 0 | J37: =IF((H37+I37=0),"-",(MAX(B37:D37)+E37)*G37) -> - | L37: =SUM(B37:D37)*0.23 -> 0 | N37: =E37*0.4*1.732 -> 0 | P37: =IF(L37+N37=0,"-",L37+(E37*0.4*1.732)) -> - | R37: EV CHARGER | S37: 1.4 | U37: =T37*S37 -> 0 | Z37: 0.6 | AB37: =AA37*Z37*1.25 -> 0
R38: 1PHASE MOTOR | S38: 2.5 | U38: =T38*S38 -> 0 | Z38: 0.5 | AB38: =AA38*Z38*1.25 -> 0
A39: 23 | G39: 1.25 | H39: =MAX(B39:D39)*G39 -> 0 | I39: =E39*G39 -> 0 | J39: =IF((H39+I39=0),"-",(MAX(B39:D39)+E39)*G39) -> - | L39: =SUM(B39:D39)*0.23 -> 0 | N39: =E39*0.4*1.732 -> 0 | P39: =IF(L39+N39=0,"-",L39+(E39*0.4*1.732)) -> - | Z39: 0.4 | AB39: =AA39*Z39*1.25 -> 0
A40: 24 | G40: 1.25 | H40: =MAX(B40:D40)*G40 -> 0 | I40: =E40*G40 -> 0 | J40: =IF((H40+I40=0),"-",(MAX(B40:D40)+E40)*G40) -> - | L40: =SUM(B40:D40)*0.23 -> 0 | N40: =E40*0.4*1.732 -> 0 | P40: =IF(L40+N40=0,"-",L40+(E40*0.4*1.732)) -> - | Z40: 0.3 | AB40: =AA40*Z40*1.25 -> 0
A42: 25 | G42: 1.25 | H42: =MAX(B42:D42)*G42 -> 0 | I42: =E42*G42 -> 0 | J42: =IF((H42+I42=0),"-",(MAX(B42:D42)+E42)*G42) -> - | L42: =SUM(B42:D42)*0.23 -> 0 | N42: =E42*0.4*1.732 -> 0 | P42: =IF(L42+N42=0,"-",L42+(E42*0.4*1.732)) -> -
A43: 26 | G43: 1.25 | H43: =MAX(B43:D43)*G43 -> 0 | I43: =E43*G43 -> 0 | J43: =IF((H43+I43=0),"-",(MAX(B43:D43)+E43)*G43) -> - | L43: =SUM(B43:D43)*0.23 -> 0 | N43: =E43*0.4*1.732 -> 0 | P43: =IF(L43+N43=0,"-",L43+(E43*0.4*1.732)) -> -
A45: 27 | G45: 1.25 | H45: =MAX(B45:D45)*G45 -> 0 | I45: =E45*G45 -> 0 | J45: =IF((H45+I45=0),"-",(MAX(B45:D45)+E45)*G45) -> - | L45: =SUM(B45:D45)*0.23 -> 0 | N45: =E45*0.4*1.732 -> 0 | P45: =IF(L45+N45=0,"-",L45+(E45*0.4*1.732)) -> -
...

Sheet Other Computation
B2: # OUTLETS | C2: VA | D2: VA | E2: AMPERES | F2: # OUTLETS | H2: *SUBJECT TO CHANGE* | Y2: KVA ASSUMPTION | AA2: VA/SQM | AC2: SQM | AE2: KVA
H3: FCU RATING | M3: INTERPOLATE
B4: 1 | C4: 180 | D4: 0.18 | E4: =C4/230 -> 0.7826087 | F4: 1 | Y4: REGULAR OFFICE | AA4: 100 | AC4: 119.36 | AE4: =AA4*AC4/1000 -> 11.936
B5: 2 | C5: 360 | D5: 0.36 | E5: =C5/230 -> 1.5652174 | F5: 2 | H5: NAME | I5: WATT | J5: HP | K5: AMPERES | M5: X | N5: X1 | O5: Y1 | P5: X2 | Q5: Y2 | R5: Y | Y5: BPO | AA5: 125 | AC5: 37.5 | AE5: =AA5*AC5/1000 -> 4.6875
B6: 3 | C6: 540 | D6: 0.54 | E6: =C6/230 -> 2.3478261 | F6: 3 | Y6: OFFICE + SHOWROOM | AA6: 125 | AC6: 119.36 | AE6: =AA6*AC6/1000 -> 14.92
B7: 4 | C7: 720 | D7: 0.72 | E7: =C7/230 -> 3.1304348 | F7: 4 | M7: 9 | N7: 7.5 | O7: 14 | P7: 10 | Q7: 18 | R7: =O7+(((M7-N7)*(Q7-O7))/(P7-N7)) -> 16.4 | Y7: LOBBY | AA7: 75 | AC7: 14.21 | AE7: =AA7*AC7/1000 -> 1.06575
B8: 5 | C8: 900 | D8: 0.9 | E8: =C8/230 -> 3.9130435 | F8: 5 | Y8: TOILET/T&B | AA8: 20 | AC8: 4.41 | AE8: =AA8*AC8/1000 -> 0.0882
B9: 6 | C9: 1080 | D9: 1.08 | E9: =C9/230 -> 4.6956522 | F9: 6 | Y9: EE ROOM | AA9: 30 | AC9: 28.08 | AE9: =AA9*AC9/1000 -> 0.8424
B10: 7 | C10: 1260 | D10: 1.26 | E10: =C10/230 -> 5.4782609 | F10: 7 | Y10: RETAIL | AA10: 400 | AC10: 119.36 | AE10: =AA10*AC10/1000 -> 47.744
B11: 8 | C11: 1440 | D11: 1.44 | E11: =C11/230 -> 6.2608696 | F11: 8 | M11: MOTOR KW TO HP | Y11: KITCHEN | AA11: 400 | AC11: 7.3 | AE11: =AA11*AC11/1000 -> 2.92
B12: 9 | C12: 1620 | D12: 1.62 | E12: =C12/230 -> 7.0434783 | F12: 9 | Y12: RENTABLE SPACE | AA12: 125 | AC12: 235 | AE12: =AA12*AC12/1000 -> 29.375
B13: 10 | C13: 1800 | D13: 1.8 | E13: =C13/230 -> 7.826087 | F13: 10 | M13: KW | O13: HP | Y13: ROOFDECK | AA13: 20 | AC13: 103 | AE13: =AA13*AC13/1000 -> 2.06
B14: 11 | C14: 1980 | D14: 1.98 | E14: =C14/230 -> 8.6086957 | F14: 11 | Y14: PRRKING | AA14: 15 | AC14: 939.41 | AE14: =AA14*AC14/1000 -> 14.09115
B15: 12 | C15: 2160 | D15: 2.16 | E15: =C15/230 -> 9.3913043 | F15: 12 | M15: 2.66 | O15: =M15/0.746 -> 3.5656836 | Y15: STORAGE | AA15: 15 | AC15: 39.81 | AE15: =AA15*AC15/1000 -> 0.59715
Y16: DINING AREA | AA16: 75 | AC16: 5.49 | AE16: =AA16*AC16/1000 -> 0.41175
Y17: LOUNGE | AA17: 75 | AC17: 111.58 | AE17: =AA17*AC17/1000 -> 8.3685
Y18: BANK | AA18: 100 | AE18: =AA18*AC18/1000 -> 0
M19: INCHES TO MILLIMETER | Q19: FEET TO METER | Y19: RETAIL(DRY) | AA19: 250 | AC19: 119.36 | AE19: =AA19*AC19/1000 -> 29.84
M21: in | O21: mm | Q21: ft | S21: m
M23: 0.5 | O23: =M23*25.4 -> 12.7 | Q23: 0.5 | S23: =Q23/3.281 -> 0.15239256
Y25: STUDIO | AA25: 2 | AE25: =AA25*AC25/1000 -> 0
Y26: ONE BED | AA26: 3 | AE26: =AA26*AC26/1000 -> 0
M27: MILLIMETER TO INCHES | Q27: METER TO FEET | Y27: 2 BED | AA27: 4 | AE27: =AA27*AC27/1000 -> 0
Y28: 3 BED | AA28: 5 | AE28: =AA28*AC28/1000 -> 0
M29: mm | O29: in | Q29: m | S29: ft | Y29: 4 BED | AA29: 6 | AE29: =AA29*AC29/1000 -> 0
M31: 25 | O31: =M31/25.4 -> 0.98425197 | Q31: 38 | S31: =Q31*3.281 -> 124.678
B38: 230V | C38: 1 PHASE | Y38: INTERPOLATE (1PHASE, 230V)
D39: 1/10 | E39: 1/8 | F39: 1/6 | G39: 1/4 | H39: 1/3 | I39: 1/2 | J39: 3/4 | K39: 1 | L39: 1 1/2 | Y39: X | Z39: X1 | AA39: Y1 | AB39: X2 | AC39: Y2 | AD39: Y | AF39: AT(x2.25) | AG39: AT(x2.50)
B40: HP | D40: 0.1 | E40: 0.125 | F40: 0.16666667 | G40: 0.25 | H40: 0.33333333 | I40: 0.5 | J40: 0.75 | K40: 1 | L40: 1.5 | M40: 2 | N40: 3 | O40: 5 | P40: 7.5 | Q40: 10 | R40: 15 | S40: 20 | T40: 25 | U40: 30 | V40: 40 | W40: 50
B41: AMPERE | D41: 1.5 | E41: 1.9 | F41: 2.2 | G41: 2.9 | H41: 3.6 | I41: 4.9 | J41: 6.9 | K41: 8 | L41: 10 | M41: 12 | N41: 17 | O41: 28 | P41: 40 | Q41: 50 | R41: 68 | S41: 88 | T41: 110 | U41: 136 | V41: 176 | W41: 216 | Y41: 3.5 | Z41: {=MAX(IF(D40:W40<Y41, D40:W40))} -> 3 | AA41: =HLOOKUP(Z41,D40:W41,2, FALSE) -> 17 | AB41: {=MIN(IF(D40:W40>Y41, D40:W40))} -> 5 | AC41: =HLOOKUP(AB41,D40:W41,2, FALSE) -> 28 | AD41: =AA41+(((Y41-Z41)*(AC41-AA41))/(AB41-Z41)) -> 19.75 | AF41: =AD41*2.25 -> 44.4375 | AG41: =AD41*2.5 -> 49.375
B44: 230V | C44: 3PHASE | Y44: INTERPOLATE (3PHASE, 230V)
B45: HP | D45: 0.5 | E45: 1 | F45: 1.5 | G45: 2 | H45: 3 | I45: 5 | J45: 7.5 | K45: 10 | L45: 15 | M45: 20 | N45: 25 | O45: 30 | P45: 40 | Q45: 50 | R45: 60 | S45: 75 | T45: 100 | U45: 125 | V45: 150 | W45: 200 | Y45: X | Z45: X1 | AA45: Y1 | AB45: X2 | AC45: Y2 | AD45: Y | AF45: AT
B46: AMPERE | D46: 2.2 | E46: 4.2 | F46: 6 | G46: 6.8 | H46: 9.6 | I46: 15.2 | J46: 22 | K46: 28 | L46: 42 | M46: 54 | N46: 68 | O46: 80 | P46: 104 | Q46: 130 | R46: 154 | S46: 192 | T46: 248 | U46: 312 | V46: 360 | W46: 480
B47: AT | D47: 15 | E47: 15 | F47: 15 | G47: 20 | H47: 20 | I47: 30 | J47: 50 | K47: 60 | L47: 100 | M47: 100 | N47: 100 | O47: 125 | P47: 150 | Q47: 200 | R47: 225 | S47: 250 | T47: 350 | U47: 500 | V47: 600 | W47: 800 | Y47: 0.75 | Z47: {=MAX(IF(D45:W45<Y47,D45:W45))} -> 0.5 | AA47: =HLOOKUP(Z47,D45:W46,2, FALSE) -> 2.2 | AB47: {=MIN(IF(D45:W45>Y47,D45:W45))} -> 1 | AC47: =HLOOKUP(AB47,D45:W46,2, FALSE) -> 4.2 | AD47: =AA47+(((Y47-Z47)*(AC47-AA47))/(AB47-Z47)) -> 3.2 | AF47: =HLOOKUP(AC47, D46:U47, 2, FALSE) -> 15
B50: 400V | C50: 3PHASE | Y50: INTERPOLATE (3PHASE, 400V)
B51: HP | D51: 0.5 | E51: 1 | F51: 1.5 | G51: 2 | H51: 3 | I51: 5 | J51: 7.5 | K51: 10 | L51: 15 | M51: 20 | N51: 25 | O51: 30 | P51: 40 | Q51: 50 | R51: 60 | S51: 75 | T51: 100 | U51: 125 | V51: 150 | W51: 200 | Y51: X | Z51: X1 | AA51: Y1 | AB51: X2 | AC51: Y2 | AD51: Y | AF51: AT
B52: AMPERE | D52: 1.3 | E52: 2.3 | F52: 3.3 | G52: 4.3 | H52: 6.1 | I52: 9.7 | J52: 14 | K52: 18 | L52: 27 | M52: 34 | N52: 44 | O52: 51 | P52: 66 | Q52: 83 | R52: 103 | S52: 128 | T52: 165 | U52: 208 | V52: 240 | W52: 320
B53: AT | D53: 15 | E53: 15 | F53: 20 | G53: 20 | H53: 20 | I53: 20 | J53: 30 | K53: 40 | L53: 60 | M53: 70 | N53: 100 | O53: 100 | P53: 100 | Q53: 125 | R53: 150 | S53: 200 | T53: 250 | U53: 300 | V53: 350 | W53: 500 | Y53: 68 | Z53: {=MAX(IF(D51:W51<Y53,D51:W51))} -> 60 | AA53: =HLOOKUP(Z53,D51:W52,2, FALSE) -> 103 | AB53: {=MIN(IF(D51:W51>Y53,D51:W51))} -> 75 | AC53: =HLOOKUP(AB53,D51:W52,2, FALSE) -> 128 | AD53: =AA53+(((Y53-Z53)*(AC53-AA53))/(AB53-Z53)) -> 116.33333 | AF53: =HLOOKUP(AC53, D52:W53, 2,FALSE ) -> 200
B57: PIPE W/ LOCKNUT APPROX DIMENSION
B58: PIPE | C58: 15 | D58: 20 | E58: 25 | F58: 32 | G58: 50 | H58: 65 | I58: 80 | J58: 90 | K58: 100 | L58: 110
...

Sheet Wiring Code
B2: LOAD SCHEDULE WIRING CODE
B3: AT | C3: CODE | D3: FEEDER WIRES AND CONDUIT SIZE | E3: CONDUIT (mmØ)
B5: 1 PHASE: 2-WIRE + GROUND | E5: IMC/EMT | F5: PVC | H5: SIZE | J5: OUTSIDE DIAMETER (mm) | M5: INSIDE DIAMETER (mm)
B6: 20 | C6: W0 | D6: 3#2.0 mmØ THHN/THWN in 15mmØ INSIDE DIAMETER CONDUIT | H6: mm | I6: in | J6: PVC SCH 40 | K6: IMC | L6: EMT | M6: PVC SCH 40 | N6: IMC | O6: EMT
B7: 30 | C7: W1 | D7: 2#5.5 sq.mm THHN/THWN and 1#2.0 mmØ THNN/THWN in 20mmØ INSIDE DIAMETER CONDUIT | H7: 15 | I7: 0.5 | J7: 21.336 | K7: 20.7 | L7: 17.93 | M7: 15.2908 | N7: 17.12 | O7: 15.89
B8: 40 | C8: W2 | D8: 2#8.0 sq.mm THHM/THWN and 1#5.5 sq.mm THNN/THWN in 20mmØ INSIDE DIAMETER CONDUIT | H8: 20 | I8: 0.75 | J8: 26.67 | K8: 26.14 | L8: 23.42 | M8: 20.4216 | N8: 22.34 | O8: 21.06
B9: 50/60 | C9: W3 | D9: 2#14 sq.mm THHN/THWN and 1#8.0 sq.mm THHN/THWN in 25mmØ INSIDE DIAMETER CONDUIT | H9: 25 | I9: 1 | J9: 33.401 | K9: 33.27 | L9: 29.54 | M9: 26.1366 | N9: 28.95 | O9: 26.8
B10: 70/80 | C10: W4 | D10: 2#22 sq.mm THHN/THWN and 1#8.0 sq.mm THHN/THWN in 32mmØ INSIDE DIAMETER CONDUIT | H10: 32 | I10: 1.25 | J10: 42.164 | K10: 41.59 | L10: 38.35 | M10: 34.544 | N10: 37.01 | O10: 35.21
B11: 100 | C11: W5 | D11: 2#30 sq.mm THHN/THWN and 1#8.0 sq.mm THNN/THWN in 32mmØ INSIDE DIAMETER CONDUIT | H11: 40 | I11: 1.5 | J11: 48.26 | K11: 47.81 | L11: 44.2 | M11: 40.386 | N11: 42.99 | O11: 41.06
B12: 125 | C12: W6 | D12: 2#50 sq.mm THHN/THWN and 1#14 sq.mm THNN/THWN in 50mmØ INSIDE DIAMETER CONDUIT | H12: 50 | I12: 2 | J12: 60.325 | K12: 59.93 | L12: 55.8 | M12: 51.9938 | N12: 52.81 | O12: 52.66
B13: 150 | C13: W7 | D13: 2#60 sq.mm THHN/THWN and 1#22 sq.mm THNN/THWN in 50mmØ INSIDE DIAMETER CONDUIT | H13: 65 | I13: 2.5 | J13: 73.025 | K13: 72.56 | L13: - | M13: 62.103 | N13: 65.44 | O13: -
B14: 200 | C14: W8 | D14: 2#80 sq.mm THHN/THWN and 1#22 sq.mm THNN/THWN in 50mmØ INSIDE DIAMETER CONDUIT | H14: 80 | I14: 3 | J14: 88.9 | K14: 88.29 | L14: - | M14: 77.2668 | N14: 81.17 | O14: -
B15: 225 | C15: W9 | D15: 2#100 sq.mm THHN/THWN and 1#30 sq.mm THNN/THWN in 65mmØ INSIDE DIAMETER CONDUIT | H15: 90 | I15: 3.5 | J15: 101.6 | K15: 100.86 | L15: - | M15: 89.4334 | N15: 93.74 | O15: -
B16: 250 | C16: W10 | D16: 2#125sq.mm THHN/THWN and 1#30 sq.mm THNN/THWN in 65mmØ INSIDE DIAMETER CONDUIT | H16: 100 | I16: 4 | J16: 114.3 | K16: 113.4 | L16: - | M16: 101.5492 | N16: 106.28 | O16: -
B17: 275 | C17: W11 | D17: 2#150 sq.mm THHN/THWN and 1#30 sq.mm THNN/THWN in 80mmØ INSIDE DIAMETER CONDUIT
B18: 300 | C18: W12 | D18: 2#200 sq.mm THHN/THWN and 1#30 sq.mm THNN/THWN in 80mmØ INSIDE DIAMETER CONDUIT
B19: 400 | C19: W13 | D19: 2#250 sq.mm THHN/THWN and 1#50 sq.mm THNN/THWN in 90mmØ INSIDE DIAMETER CONDUIT
B21: 3 PHASE: 3-WIRE + GROUND : FOR ACCU, EF, PUMP, JF | E21: IMC/EMT | F21: PVC | H21: PERCENT FILL COMPUTATION
B22: 20 | C22: X0 | D22: 4#2.0 mmØ THHN/THWN in 15mmØ INSIDE DIAMETER CONDUIT | H22: CONDUIT
B23: 30 | C23: X1 | D23: 3#5.5 sq.mm THHN/THWN and 1#2.0 mmØ THNN/THWN in 20mmØ INSIDE DIAMETER CONDUIT | H23: Wires | K23: Conduit
B24: 40 | C24: X2 | D24: 3#8.0 sq.mm THHN/THWN and 1#5.5 sq.mm THNN/THWN in 25mmØ INSIDE DIAMETER CONDUIT | H24: Wire Dia | I24: # of Wires | J24: Area | K24: Diameter | L24: Area | M24: %Fill
B25: 50/60 | C25: X3 | D25: 3#14 sq.mm THHN/THWN and 1#8.0 sq.mm THNN/THWN in 25mmØ INSIDE DIAMETER CONDUIT
B26: 70/80 | C26: X4 | D26: 3#22 sq.mm THHN/THWN and 1#8.0 sq.mm THNN/THWN in 32mmØ INSIDE DIAMETER CONDUIT | H26: 3 | I26: 10 | J26: =((H26^2)*PI()/4)*I26 -> 70.685835 | K26: 15 | L26: =(K26^2)*PI()/4 -> 176.71459 | M26: =IF(L26<1,"-",J26/L26*100) -> 40 | N26: =IF(IF(I26>3, 40, VLOOKUP(I26, H29:K31, 4,FALSE))>=M26,"PASS","FAIL") -> PASS
B27: 100 | C27: X5 | D27: 3#30 sq.mm THHN/THWN and 1#8.0 sq.mm THNN/THWN in 32mmØ INSIDE DIAMETER CONDUIT
B28: 125 | C28: X6 | D28: 3#50 sq.mm THHN/THWN and 1#14 sq.mm THNN/THWN in 50mmØ INSIDE DIAMETER CONDUIT | H28: MINIMUM PERCENT FILL
B29: 150 | C29: X7 | D29: 3#60 sq.mm THHN/THWN and 1#22 sq.mm THNN/THWN in 50mmØ INSIDE DIAMETER CONDUIT | H29: 1 | I29: WIRE | K29: 53
B30: 200 | C30: X8 | D30: 3#80 sq.mm THHN/THWN and 1#22 sq.mm THNN/THWN in 50mmØ INSIDE DIAMETER CONDUIT | H30: 2 | I30: WIRES | K30: 31
B31: 225 | C31: X9 | D31: 3#100 sq.mm THHN/THWN and 1#30 sq.mm THNN/THWN in 65mmØ INSIDE DIAMETER CONDUIT | H31: 3 | I31: OR MORE | K31: 40
B32: 250 | C32: X10 | D32: 3#125sq.mm THHN/THWN and 1#30 sq.mm THNN/THWN in 65mmØ INSIDE DIAMETER CONDUIT
B33: 275 | C33: X11 | D33: 3#150 sq.mm THHN/THWN and 1#30 sq.mm THNN/THWN in 80mmØ INSIDE DIAMETER CONDUIT
B34: 300 | C34: X12 | D34: 3#200 sq.mm THHN/THWN and 1#30 sq.mm THNN/THWN in 80mmØ INSIDE DIAMETER CONDUIT
B35: 400 | C35: X13 | D35: 3#250 sq.mm THHN/THWN and 1#50 sq.mm THNN/THWN in 90mmØ INSIDE DIAMETER CONDUIT | H35: PERCENT FILL COMPUTATION
H36: CABLE TRAY
B37: 3 PHASE: 3-WIRE + NEUTRAL + GROUND : FOR MAINS | E37: IMC/EMT | F37: PVC | H37: Wires
B38: 20 | C38: Y0 | D38: 5#2.0 mmØ THHN/THWN in 15mmØ INSIDE DIAMETER CONDUIT | H38: Wire Dia | I38: # of Wires | J38: Ground Dia | K38: Area | L38: Width | M38: Height | N38: Area | O38: %Fill | P38: Status
B39: 30 | C39: Y1 | D39: 4#5.5 sq.mm THHM/THWN and 1#2.0 mmØ THNN/THWN in 20mmØ INSIDE DIAMETER CONDUIT
B40: 40 | C40: Y2 | D40: 4#8.0 sq.mm THHM/THWN and 1#5.5 sq.mm THNN/THWN in 25mmØ INSIDE DIAMETER CONDUIT | H40: 27.9 | I40: 16 | K40: =(((H40^2)*PI()/4)*I40)+((J40^2)*PI()/4) -> 9781.7885 | L40: 400 | M40: 150 | N40: =L40*M40 -> 60000 | O40: =IF(N40<=0,"-",(K40/N40)*100) -> 16.302981 | P40: =IF(O40<=20, "PASS", "FAIL") -> PASS
B41: 50/60 | C41: Y3 | D41: 4#14 sq.mm THHM/THWN and 1#8.0 sq.mm THNN/THWN in 25mmØ INSIDE DIAMETER CONDUIT
B42: 70/80 | C42: Y4 | D42: 4#22 sq.mm THHM/THWN and 1#8.0 sq.mm THNN/THWN in 32mmØ INSIDE DIAMETER CONDUIT
B43: 100 | C43: Y5 | D43: 4#30 sq.mm THHM/THWN and 1#8.0 sq.mm THNN/THWN in 32mmØ INSIDE DIAMETER CONDUIT | H43: WXY-0 | I43: 15mmØ INSIDE DIAMETER CONDUIT
...

Sheet Voltage Drop
B2: Voltage Drop (Vd) = kDI x √(R²+X²) / n | J2: Phase | K2: k | M2: Total VD | N2: =SUM(Table1[Voltage Drop]) -> 6.2581326
B3: Voltage Drop (Vd) = kDI x [R*cos(Ө)+X*sin(Ө)] / n | J3: 1 | K3: 2 | M3: Total % VD | N3: =SUM(Table1[%VD]) -> 0.027209272
J4: 3 | K4: 1.732
B5: k = Constant (2 for single phase, 1.732 for three phase
B6: D = Distance or Length of the conductor (m) | J6: Conduit Type
B7: I = Current in Amperes | J7: PVC
B8: R = Line AC Resistance per 305m | J8: Metal
B9: X = Line AC Reactance per 305m
B10: Ө = cos(pf)
B11: pf = Power Factor, Assumed 85%
B12: n = Number of wire per phase or the number of sets
B16: VD Number | C16: Phase | D16: Column1 | E16: k | F16: D | G16: I | H16: n | I16: Wire Code | J16: Conductor Type | K16: Wire Dia (mm²) | L16: Conduit | M16: R | N16: X | O16: Voltage Drop | P16: %VD
B17: 1 | C17: 3 | D17: 230 | E17: =_xlfn.IFNA(VLOOKUP(Table1[[#This Row],[Phase]],$J$2:$K$4, 2,FALSE), "-") -> 1.732 | F17: 8 | G17: 200 | H17: 1 | I17: X8 | J17: =_xlfn.IFNA(VLOOKUP(Table1[[#This Row],[Wire Code]], 'Table Reference'!$Z$6:$AB$111, 3,FALSE), "-") -> CU | K17: =_xlfn.IFNA(VLOOKUP(VLOOKUP(Table1[[#This Row],[Wire Code]], 'Table Reference'!$Z$6:$AA$111, 2,FALSE), 'Table Reference'!$AD$6:$AE$26, 2, FALSE), "-") -> 80 | L17: Metal | M17: =_xlfn.IFNA(VLOOKUP(Table1[[#This Row],[Wire Dia (mm²)]], 'Table Reference'!$B$7:$K$27, IF(Table1[[#This Row],[Conductor Type]]="CU", IF(Table1[[#This Row],[Conduit]]="PVC", 5, 7), IF(Table1[[#This Row],[Conduit]]="PVC", 8, 10)),FALSE), "-") -> 0.079 | N17: =_xlfn.IFNA(_xlfn.IFS(Table1[[#This Row],[Conduit]]="PVC", VLOOKUP(Table1[[#This Row],[Wire Dia (mm²)]], 'Table Reference'!$B$7:$E$27, 3, FALSE), Table1[[#This Row],[Conduit]]="Metal", VLOOKUP(Table1[[#This Row],[Wire Dia (mm²)]], 'Table Reference'!$B$7:$E$27, 4, FALSE)), "-") -> 0.052 | O17: =IFERROR(Table1[[#This Row],[k]]*Table1[[#This Row],[D]]*Table1[[#This Row],[I]]*(((Table1[[#This Row],[R]]*0.85)/305)+((Table1[[#This Row],[X]]*0.53)/305))/Table1[[#This Row],[n]], "-") -> 0.86052574 | P17: =IFERROR(Table1[[#This Row],[Voltage Drop]]/Table1[[#This Row],[Column1]], "-") -> 0.0037414163
B18: 2 | C18: 1 | D18: 230 | E18: =_xlfn.IFNA(VLOOKUP(Table1[[#This Row],[Phase]],$J$2:$K$4, 2,FALSE), "-") -> 2 | F18: 49.16 | G18: 16 | H18: 1 | I18: W1 | J18: =_xlfn.IFNA(VLOOKUP(Table1[[#This Row],[Wire Code]], 'Table Reference'!$Z$6:$AB$111, 3,FALSE), "-") -> CU | K18: =_xlfn.IFNA(VLOOKUP(VLOOKUP(Table1[[#This Row],[Wire Code]], 'Table Reference'!$Z$6:$AA$111, 2,FALSE), 'Table Reference'!$AD$6:$AE$26, 2, FALSE), "-") -> 5.5 | L18: PVC | M18: =_xlfn.IFNA(VLOOKUP(Table1[[#This Row],[Wire Dia (mm²)]], 'Table Reference'!$B$7:$K$27, IF(Table1[[#This Row],[Conductor Type]]="CU", IF(Table1[[#This Row],[Conduit]]="PVC", 5, 7), IF(Table1[[#This Row],[Conduit]]="PVC", 8, 10)),FALSE), "-") -> 1.2 | N18: =_xlfn.IFNA(_xlfn.IFS(Table1[[#This Row],[Conduit]]="PVC", VLOOKUP(Table1[[#This Row],[Wire Dia (mm²)]], 'Table Reference'!$B$7:$E$27, 3, FALSE), Table1[[#This Row],[Conduit]]="Metal", VLOOKUP(Table1[[#This Row],[Wire Dia (mm²)]], 'Table Reference'!$B$7:$E$27, 4, FALSE)), "-") -> 0.05 | O18: =IFERROR(Table1[[#This Row],[k]]*Table1[[#This Row],[D]]*Table1[[#This Row],[I]]*(((Table1[[#This Row],[R]]*0.85)/305)+((Table1[[#This Row],[X]]*0.53)/305))/Table1[[#This Row],[n]], "-") -> 5.3976068 | P18: =IFERROR(Table1[[#This Row],[Voltage Drop]]/Table1[[#This Row],[Column1]], "-") -> 0.023467856
B19: 3 | E19: =_xlfn.IFNA(VLOOKUP(Table1[[#This Row],[Phase]],$J$2:$K$4, 2,FALSE), "-") -> - | J19: =_xlfn.IFNA(VLOOKUP(Table1[[#This Row],[Wire Code]], 'Table Reference'!$Z$6:$AB$111, 3,FALSE), "-") -> - | K19: =_xlfn.IFNA(VLOOKUP(VLOOKUP(Table1[[#This Row],[Wire Code]], 'Table Reference'!$Z$6:$AA$111, 2,FALSE), 'Table Reference'!$AD$6:$AE$26, 2, FALSE), "-") -> - | M19: =_xlfn.IFNA(VLOOKUP(Table1[[#This Row],[Wire Dia (mm²)]], 'Table Reference'!$B$7:$K$27, IF(Table1[[#This Row],[Conductor Type]]="CU", IF(Table1[[#This Row],[Conduit]]="PVC", 5, 7), IF(Table1[[#This Row],[Conduit]]="PVC", 8, 10)),FALSE), "-") -> - | N19: =_xlfn.IFNA(_xlfn.IFS(Table1[[#This Row],[Conduit]]="PVC", VLOOKUP(Table1[[#This Row],[Wire Dia (mm²)]], 'Table Reference'!$B$7:$E$27, 3, FALSE), Table1[[#This Row],[Conduit]]="Metal", VLOOKUP(Table1[[#This Row],[Wire Dia (mm²)]], 'Table Reference'!$B$7:$E$27, 4, FALSE)), "-") -> - | O19: =IFERROR(Table1[[#This Row],[k]]*Table1[[#This Row],[D]]*Table1[[#This Row],[I]]*(((Table1[[#This Row],[R]]*0.85)/305)+((Table1[[#This Row],[X]]*0.53)/305))/Table1[[#This Row],[n]], "-") -> - | P19: =IFERROR(Table1[[#This Row],[Voltage Drop]]/Table1[[#This Row],[Column1]], "-") -> -
B20: 4 | E20: =_xlfn.IFNA(VLOOKUP(Table1[[#This Row],[Phase]],$J$2:$K$4, 2,FALSE), "-") -> - | J20: =_xlfn.IFNA(VLOOKUP(Table1[[#This Row],[Wire Code]], 'Table Reference'!$Z$6:$AB$111, 3,FALSE), "-") -> - | K20: =_xlfn.IFNA(VLOOKUP(VLOOKUP(Table1[[#This Row],[Wire Code]], 'Table Reference'!$Z$6:$AA$111, 2,FALSE), 'Table Reference'!$AD$6:$AE$26, 2, FALSE), "-") -> - | M20: =_xlfn.IFNA(VLOOKUP(Table1[[#This Row],[Wire Dia (mm²)]], 'Table Reference'!$B$7:$K$27, IF(Table1[[#This Row],[Conductor Type]]="CU", IF(Table1[[#This Row],[Conduit]]="PVC", 5, 7), IF(Table1[[#This Row],[Conduit]]="PVC", 8, 10)),FALSE), "-") -> - | N20: =_xlfn.IFNA(_xlfn.IFS(Table1[[#This Row],[Conduit]]="PVC", VLOOKUP(Table1[[#This Row],[Wire Dia (mm²)]], 'Table Reference'!$B$7:$E$27, 3, FALSE), Table1[[#This Row],[Conduit]]="Metal", VLOOKUP(Table1[[#This Row],[Wire Dia (mm²)]], 'Table Reference'!$B$7:$E$27, 4, FALSE)), "-") -> - | O20: =IFERROR(Table1[[#This Row],[k]]*Table1[[#This Row],[D]]*Table1[[#This Row],[I]]*(((Table1[[#This Row],[R]]*0.85)/305)+((Table1[[#This Row],[X]]*0.53)/305))/Table1[[#This Row],[n]], "-") -> - | P20: =IFERROR(Table1[[#This Row],[Voltage Drop]]/Table1[[#This Row],[Column1]], "-") -> -
B21: 5 | E21: =_xlfn.IFNA(VLOOKUP(Table1[[#This Row],[Phase]],$J$2:$K$4, 2,FALSE), "-") -> - | J21: =_xlfn.IFNA(VLOOKUP(Table1[[#This Row],[Wire Code]], 'Table Reference'!$Z$6:$AB$111, 3,FALSE), "-") -> - | K21: =_xlfn.IFNA(VLOOKUP(VLOOKUP(Table1[[#This Row],[Wire Code]], 'Table Reference'!$Z$6:$AA$111, 2,FALSE), 'Table Reference'!$AD$6:$AE$26, 2, FALSE), "-") -> - | M21: =_xlfn.IFNA(VLOOKUP(Table1[[#This Row],[Wire Dia (mm²)]], 'Table Reference'!$B$7:$K$27, IF(Table1[[#This Row],[Conductor Type]]="CU", IF(Table1[[#This Row],[Conduit]]="PVC", 5, 7), IF(Table1[[#This Row],[Conduit]]="PVC", 8, 10)),FALSE), "-") -> - | N21: =_xlfn.IFNA(_xlfn.IFS(Table1[[#This Row],[Conduit]]="PVC", VLOOKUP(Table1[[#This Row],[Wire Dia (mm²)]], 'Table Reference'!$B$7:$E$27, 3, FALSE), Table1[[#This Row],[Conduit]]="Metal", VLOOKUP(Table1[[#This Row],[Wire Dia (mm²)]], 'Table Reference'!$B$7:$E$27, 4, FALSE)), "-") -> - | O21: =IFERROR(Table1[[#This Row],[k]]*Table1[[#This Row],[D]]*Table1[[#This Row],[I]]*(((Table1[[#This Row],[R]]*0.85)/305)+((Table1[[#This Row],[X]]*0.53)/305))/Table1[[#This Row],[n]], "-") -> - | P21: =IFERROR(Table1[[#This Row],[Voltage Drop]]/Table1[[#This Row],[Column1]], "-") -> -
B22: 6 | E22: =_xlfn.IFNA(VLOOKUP(Table1[[#This Row],[Phase]],$J$2:$K$4, 2,FALSE), "-") -> - | J22: =_xlfn.IFNA(VLOOKUP(Table1[[#This Row],[Wire Code]], 'Table Reference'!$Z$6:$AB$111, 3,FALSE), "-") -> - | K22: =_xlfn.IFNA(VLOOKUP(VLOOKUP(Table1[[#This Row],[Wire Code]], 'Table Reference'!$Z$6:$AA$111, 2,FALSE), 'Table Reference'!$AD$6:$AE$26, 2, FALSE), "-") -> - | M22: =_xlfn.IFNA(VLOOKUP(Table1[[#This Row],[Wire Dia (mm²)]], 'Table Reference'!$B$7:$K$27, IF(Table1[[#This Row],[Conductor Type]]="CU", IF(Table1[[#This Row],[Conduit]]="PVC", 5, 7), IF(Table1[[#This Row],[Conduit]]="PVC", 8, 10)),FALSE), "-") -> - | N22: =_xlfn.IFNA(_xlfn.IFS(Table1[[#This Row],[Conduit]]="PVC", VLOOKUP(Table1[[#This Row],[Wire Dia (mm²)]], 'Table Reference'!$B$7:$E$27, 3, FALSE), Table1[[#This Row],[Conduit]]="Metal", VLOOKUP(Table1[[#This Row],[Wire Dia (mm²)]], 'Table Reference'!$B$7:$E$27, 4, FALSE)), "-") -> - | O22: =IFERROR(Table1[[#This Row],[k]]*Table1[[#This Row],[D]]*Table1[[#This Row],[I]]*(((Table1[[#This Row],[R]]*0.85)/305)+((Table1[[#This Row],[X]]*0.53)/305))/Table1[[#This Row],[n]], "-") -> - | P22: =IFERROR(Table1[[#This Row],[Voltage Drop]]/Table1[[#This Row],[Column1]], "-") -> -
B23: 7 | E23: =_xlfn.IFNA(VLOOKUP(Table1[[#This Row],[Phase]],$J$2:$K$4, 2,FALSE), "-") -> - | J23: =_xlfn.IFNA(VLOOKUP(Table1[[#This Row],[Wire Code]], 'Table Reference'!$Z$6:$AB$111, 3,FALSE), "-") -> - | K23: =_xlfn.IFNA(VLOOKUP(VLOOKUP(Table1[[#This Row],[Wire Code]], 'Table Reference'!$Z$6:$AA$111, 2,FALSE), 'Table Reference'!$AD$6:$AE$26, 2, FALSE), "-") -> - | M23: =_xlfn.IFNA(VLOOKUP(Table1[[#This Row],[Wire Dia (mm²)]], 'Table Reference'!$B$7:$K$27, IF(Table1[[#This Row],[Conductor Type]]="CU", IF(Table1[[#This Row],[Conduit]]="PVC", 5, 7), IF(Table1[[#This Row],[Conduit]]="PVC", 8, 10)),FALSE), "-") -> - | N23: =_xlfn.IFNA(_xlfn.IFS(Table1[[#This Row],[Conduit]]="PVC", VLOOKUP(Table1[[#This Row],[Wire Dia (mm²)]], 'Table Reference'!$B$7:$E$27, 3, FALSE), Table1[[#This Row],[Conduit]]="Metal", VLOOKUP(Table1[[#This Row],[Wire Dia (mm²)]], 'Table Reference'!$B$7:$E$27, 4, FALSE)), "-") -> - | O23: =IFERROR(Table1[[#This Row],[k]]*Table1[[#This Row],[D]]*Table1[[#This Row],[I]]*(((Table1[[#This Row],[R]]*0.85)/305)+((Table1[[#This Row],[X]]*0.53)/305))/Table1[[#This Row],[n]], "-") -> - | P23: =IFERROR(Table1[[#This Row],[Voltage Drop]]/Table1[[#This Row],[Column1]], "-") -> -
B24: 8 | E24: =_xlfn.IFNA(VLOOKUP(Table1[[#This Row],[Phase]],$J$2:$K$4, 2,FALSE), "-") -> - | J24: =_xlfn.IFNA(VLOOKUP(Table1[[#This Row],[Wire Code]], 'Table Reference'!$Z$6:$AB$111, 3,FALSE), "-") -> - | K24: =_xlfn.IFNA(VLOOKUP(VLOOKUP(Table1[[#This Row],[Wire Code]], 'Table Reference'!$Z$6:$AA$111, 2,FALSE), 'Table Reference'!$AD$6:$AE$26, 2, FALSE), "-") -> - | M24: =_xlfn.IFNA(VLOOKUP(Table1[[#This Row],[Wire Dia (mm²)]], 'Table Reference'!$B$7:$K$27, IF(Table1[[#This Row],[Conductor Type]]="CU", IF(Table1[[#This Row],[Conduit]]="PVC", 5, 7), IF(Table1[[#This Row],[Conduit]]="PVC", 8, 10)),FALSE), "-") -> - | N24: =_xlfn.IFNA(_xlfn.IFS(Table1[[#This Row],[Conduit]]="PVC", VLOOKUP(Table1[[#This Row],[Wire Dia (mm²)]], 'Table Reference'!$B$7:$E$27, 3, FALSE), Table1[[#This Row],[Conduit]]="Metal", VLOOKUP(Table1[[#This Row],[Wire Dia (mm²)]], 'Table Reference'!$B$7:$E$27, 4, FALSE)), "-") -> - | O24: =IFERROR(Table1[[#This Row],[k]]*Table1[[#This Row],[D]]*Table1[[#This Row],[I]]*(((Table1[[#This Row],[R]]*0.85)/305)+((Table1[[#This Row],[X]]*0.53)/305))/Table1[[#This Row],[n]], "-") -> - | P24: =IFERROR(Table1[[#This Row],[Voltage Drop]]/Table1[[#This Row],[Column1]], "-") -> -
B25: 9 | E25: =_xlfn.IFNA(VLOOKUP(Table1[[#This Row],[Phase]],$J$2:$K$4, 2,FALSE), "-") -> - | J25: =_xlfn.IFNA(VLOOKUP(Table1[[#This Row],[Wire Code]], 'Table Reference'!$Z$6:$AB$111, 3,FALSE), "-") -> - | K25: =_xlfn.IFNA(VLOOKUP(VLOOKUP(Table1[[#This Row],[Wire Code]], 'Table Reference'!$Z$6:$AA$111, 2,FALSE), 'Table Reference'!$AD$6:$AE$26, 2, FALSE), "-") -> - | M25: =_xlfn.IFNA(VLOOKUP(Table1[[#This Row],[Wire Dia (mm²)]], 'Table Reference'!$B$7:$K$27, IF(Table1[[#This Row],[Conductor Type]]="CU", IF(Table1[[#This Row],[Conduit]]="PVC", 5, 7), IF(Table1[[#This Row],[Conduit]]="PVC", 8, 10)),FALSE), "-") -> - | N25: =_xlfn.IFNA(_xlfn.IFS(Table1[[#This Row],[Conduit]]="PVC", VLOOKUP(Table1[[#This Row],[Wire Dia (mm²)]], 'Table Reference'!$B$7:$E$27, 3, FALSE), Table1[[#This Row],[Conduit]]="Metal", VLOOKUP(Table1[[#This Row],[Wire Dia (mm²)]], 'Table Reference'!$B$7:$E$27, 4, FALSE)), "-") -> - | O25: =IFERROR(Table1[[#This Row],[k]]*Table1[[#This Row],[D]]*Table1[[#This Row],[I]]*(((Table1[[#This Row],[R]]*0.85)/305)+((Table1[[#This Row],[X]]*0.53)/305))/Table1[[#This Row],[n]], "-") -> - | P25: =IFERROR(Table1[[#This Row],[Voltage Drop]]/Table1[[#This Row],[Column1]], "-") -> -
B26: 10 | E26: =_xlfn.IFNA(VLOOKUP(Table1[[#This Row],[Phase]],$J$2:$K$4, 2,FALSE), "-") -> - | J26: =_xlfn.IFNA(VLOOKUP(Table1[[#This Row],[Wire Code]], 'Table Reference'!$Z$6:$AB$111, 3,FALSE), "-") -> - | K26: =_xlfn.IFNA(VLOOKUP(VLOOKUP(Table1[[#This Row],[Wire Code]], 'Table Reference'!$Z$6:$AA$111, 2,FALSE), 'Table Reference'!$AD$6:$AE$26, 2, FALSE), "-") -> - | M26: =_xlfn.IFNA(VLOOKUP(Table1[[#This Row],[Wire Dia (mm²)]], 'Table Reference'!$B$7:$K$27, IF(Table1[[#This Row],[Conductor Type]]="CU", IF(Table1[[#This Row],[Conduit]]="PVC", 5, 7), IF(Table1[[#This Row],[Conduit]]="PVC", 8, 10)),FALSE), "-") -> - | N26: =_xlfn.IFNA(_xlfn.IFS(Table1[[#This Row],[Conduit]]="PVC", VLOOKUP(Table1[[#This Row],[Wire Dia (mm²)]], 'Table Reference'!$B$7:$E$27, 3, FALSE), Table1[[#This Row],[Conduit]]="Metal", VLOOKUP(Table1[[#This Row],[Wire Dia (mm²)]], 'Table Reference'!$B$7:$E$27, 4, FALSE)), "-") -> - | O26: =IFERROR(Table1[[#This Row],[k]]*Table1[[#This Row],[D]]*Table1[[#This Row],[I]]*(((Table1[[#This Row],[R]]*0.85)/305)+((Table1[[#This Row],[X]]*0.53)/305))/Table1[[#This Row],[n]], "-") -> - | P26: =IFERROR(Table1[[#This Row],[Voltage Drop]]/Table1[[#This Row],[Column1]], "-") -> -
B27: 11 | E27: =_xlfn.IFNA(VLOOKUP(Table1[[#This Row],[Phase]],$J$2:$K$4, 2,FALSE), "-") -> - | J27: =_xlfn.IFNA(VLOOKUP(Table1[[#This Row],[Wire Code]], 'Table Reference'!$Z$6:$AB$111, 3,FALSE), "-") -> - | K27: =_xlfn.IFNA(VLOOKUP(VLOOKUP(Table1[[#This Row],[Wire Code]], 'Table Reference'!$Z$6:$AA$111, 2,FALSE), 'Table Reference'!$AD$6:$AE$26, 2, FALSE), "-") -> - | M27: =_xlfn.IFNA(VLOOKUP(Table1[[#This Row],[Wire Dia (mm²)]], 'Table Reference'!$B$7:$K$27, IF(Table1[[#This Row],[Conductor Type]]="CU", IF(Table1[[#This Row],[Conduit]]="PVC", 5, 7), IF(Table1[[#This Row],[Conduit]]="PVC", 8, 10)),FALSE), "-") -> - | N27: =_xlfn.IFNA(_xlfn.IFS(Table1[[#This Row],[Conduit]]="PVC", VLOOKUP(Table1[[#This Row],[Wire Dia (mm²)]], 'Table Reference'!$B$7:$E$27, 3, FALSE), Table1[[#This Row],[Conduit]]="Metal", VLOOKUP(Table1[[#This Row],[Wire Dia (mm²)]], 'Table Reference'!$B$7:$E$27, 4, FALSE)), "-") -> - | O27: =IFERROR(Table1[[#This Row],[k]]*Table1[[#This Row],[D]]*Table1[[#This Row],[I]]*(((Table1[[#This Row],[R]]*0.85)/305)+((Table1[[#This Row],[X]]*0.53)/305))/Table1[[#This Row],[n]], "-") -> - | P27: =IFERROR(Table1[[#This Row],[Voltage Drop]]/Table1[[#This Row],[Column1]], "-") -> -
B28: 12 | E28: =_xlfn.IFNA(VLOOKUP(Table1[[#This Row],[Phase]],$J$2:$K$4, 2,FALSE), "-") -> - | J28: =_xlfn.IFNA(VLOOKUP(Table1[[#This Row],[Wire Code]], 'Table Reference'!$Z$6:$AB$111, 3,FALSE), "-") -> - | K28: =_xlfn.IFNA(VLOOKUP(VLOOKUP(Table1[[#This Row],[Wire Code]], 'Table Reference'!$Z$6:$AA$111, 2,FALSE), 'Table Reference'!$AD$6:$AE$26, 2, FALSE), "-") -> - | M28: =_xlfn.IFNA(VLOOKUP(Table1[[#This Row],[Wire Dia (mm²)]], 'Table Reference'!$B$7:$K$27, IF(Table1[[#This Row],[Conductor Type]]="CU", IF(Table1[[#This Row],[Conduit]]="PVC", 5, 7), IF(Table1[[#This Row],[Conduit]]="PVC", 8, 10)),FALSE), "-") -> - | N28: =_xlfn.IFNA(_xlfn.IFS(Table1[[#This Row],[Conduit]]="PVC", VLOOKUP(Table1[[#This Row],[Wire Dia (mm²)]], 'Table Reference'!$B$7:$E$27, 3, FALSE), Table1[[#This Row],[Conduit]]="Metal", VLOOKUP(Table1[[#This Row],[Wire Dia (mm²)]], 'Table Reference'!$B$7:$E$27, 4, FALSE)), "-") -> - | O28: =IFERROR(Table1[[#This Row],[k]]*Table1[[#This Row],[D]]*Table1[[#This Row],[I]]*(((Table1[[#This Row],[R]]*0.85)/305)+((Table1[[#This Row],[X]]*0.53)/305))/Table1[[#This Row],[n]], "-") -> - | P28: =IFERROR(Table1[[#This Row],[Voltage Drop]]/Table1[[#This Row],[Column1]], "-") -> -
B29: 13 | E29: =_xlfn.IFNA(VLOOKUP(Table1[[#This Row],[Phase]],$J$2:$K$4, 2,FALSE), "-") -> - | J29: =_xlfn.IFNA(VLOOKUP(Table1[[#This Row],[Wire Code]], 'Table Reference'!$Z$6:$AB$111, 3,FALSE), "-") -> - | K29: =_xlfn.IFNA(VLOOKUP(VLOOKUP(Table1[[#This Row],[Wire Code]], 'Table Reference'!$Z$6:$AA$111, 2,FALSE), 'Table Reference'!$AD$6:$AE$26, 2, FALSE), "-") -> - | M29: =_xlfn.IFNA(VLOOKUP(Table1[[#This Row],[Wire Dia (mm²)]], 'Table Reference'!$B$7:$K$27, IF(Table1[[#This Row],[Conductor Type]]="CU", IF(Table1[[#This Row],[Conduit]]="PVC", 5, 7), IF(Table1[[#This Row],[Conduit]]="PVC", 8, 10)),FALSE), "-") -> - | N29: =_xlfn.IFNA(_xlfn.IFS(Table1[[#This Row],[Conduit]]="PVC", VLOOKUP(Table1[[#This Row],[Wire Dia (mm²)]], 'Table Reference'!$B$7:$E$27, 3, FALSE), Table1[[#This Row],[Conduit]]="Metal", VLOOKUP(Table1[[#This Row],[Wire Dia (mm²)]], 'Table Reference'!$B$7:$E$27, 4, FALSE)), "-") -> - | O29: =IFERROR(Table1[[#This Row],[k]]*Table1[[#This Row],[D]]*Table1[[#This Row],[I]]*(((Table1[[#This Row],[R]]*0.85)/305)+((Table1[[#This Row],[X]]*0.53)/305))/Table1[[#This Row],[n]], "-") -> - | P29: =IFERROR(Table1[[#This Row],[Voltage Drop]]/Table1[[#This Row],[Column1]], "-") -> -
B30: 14 | E30: =_xlfn.IFNA(VLOOKUP(Table1[[#This Row],[Phase]],$J$2:$K$4, 2,FALSE), "-") -> - | J30: =_xlfn.IFNA(VLOOKUP(Table1[[#This Row],[Wire Code]], 'Table Reference'!$Z$6:$AB$111, 3,FALSE), "-") -> - | K30: =_xlfn.IFNA(VLOOKUP(VLOOKUP(Table1[[#This Row],[Wire Code]], 'Table Reference'!$Z$6:$AA$111, 2,FALSE), 'Table Reference'!$AD$6:$AE$26, 2, FALSE), "-") -> - | M30: =_xlfn.IFNA(VLOOKUP(Table1[[#This Row],[Wire Dia (mm²)]], 'Table Reference'!$B$7:$K$27, IF(Table1[[#This Row],[Conductor Type]]="CU", IF(Table1[[#This Row],[Conduit]]="PVC", 5, 7), IF(Table1[[#This Row],[Conduit]]="PVC", 8, 10)),FALSE), "-") -> - | N30: =_xlfn.IFNA(_xlfn.IFS(Table1[[#This Row],[Conduit]]="PVC", VLOOKUP(Table1[[#This Row],[Wire Dia (mm²)]], 'Table Reference'!$B$7:$E$27, 3, FALSE), Table1[[#This Row],[Conduit]]="Metal", VLOOKUP(Table1[[#This Row],[Wire Dia (mm²)]], 'Table Reference'!$B$7:$E$27, 4, FALSE)), "-") -> - | O30: =IFERROR(Table1[[#This Row],[k]]*Table1[[#This Row],[D]]*Table1[[#This Row],[I]]*(((Table1[[#This Row],[R]]*0.85)/305)+((Table1[[#This Row],[X]]*0.53)/305))/Table1[[#This Row],[n]], "-") -> - | P30: =IFERROR(Table1[[#This Row],[Voltage Drop]]/Table1[[#This Row],[Column1]], "-") -> -
... B41: 25 | E41: =_xlfn.IFNA(VLOOKUP(Table1[[#This Row],[Phase]],$J$2:$K$4, 2,FALSE), "-") -> - | J41: =_xlfn.IFNA(VLOOKUP(Table1[[#This Row],[Wire Code]], 'Table Reference'!$Z$6:$AB$111, 3,FALSE), "-") -> - | K41: =_xlfn.IFNA(VLOOKUP(VLOOKUP(Table1[[#This Row],[Wire Code]], 'Table Reference'!$Z$6:$AA$111, 2,FALSE), 'Table Reference'!$AD$6:$AE$26, 2, FALSE), "-") -> - | M41: =_xlfn.IFNA(VLOOKUP(Table1[[#This Row],[Wire Dia (mm²)]], 'Table Reference'!$B$7:$K$27, IF(Table1[[#This Row],[Conductor Type]]="CU", IF(Table1[[#This Row],[Conduit]]="PVC", 5, 7), IF(Table1[[#This Row],[Conduit]]="PVC", 8, 10)),FALSE), "-") -> - | N41: =_xlfn.IFNA(_xlfn.IFS(Table1[[#This Row],[Conduit]]="PVC", VLOOKUP(Table1[[#This Row],[Wire Dia (mm²)]], 'Table Reference'!$B$7:$E$27, 3, FALSE), Table1[[#This Row],[Conduit]]="Metal", VLOOKUP(Table1[[#This Row],[Wire Dia (mm²)]], 'Table Reference'!$B$7:$E$27, 4, FALSE)), "-") -> - | O41: =IFERROR(Table1[[#This Row],[k]]*Table1[[#This Row],[D]]*Table1[[#This Row],[I]]*(((Table1[[#This Row],[R]]*0.85)/305)+((Table1[[#This Row],[X]]*0.53)/305))/Table1[[#This Row],[n]], "-") -> - | P41: =IFERROR(Table1[[#This Row],[Voltage Drop]]/Table1[[#This Row],[Column1]], "-") -> -

Sheet Short Circuit Analysis
B2: Short Circuit Calculation
J3: Phase
B4: IFL (3 Phase) = VA/(V*1.732) | K4: V Factor | L4: k | R4: METER | S4: FEET
B5: IFL (1 Phase) = VA/V | J5: 3 | K5: 1.732 | L5: 1.732
B6: M (Transformer) = 100/(Transformer %Z) | J6: 1 | K6: 1 | L6: 2 | R6: 18.12 | S6: =R6*3.28084 -> 59.448821
B7: I(SC) = IFL * M
B8: f = (k*L*I)/C*n*V
B9: M = 1/(1 + f) | R9: FEET | S9: METER
B11: IFL: Full Load Ampere | R11: 95.14 | S11: =R11/3.28084 -> 28.998671
B12: f: Factor at Fault Point | J12: NOTE:
B13: k: 1.732 (3-Phase), 2 (Single Phase) | J13: 3SC = 3 Single Conductors
B14: M: Multiplier at point f | J14: 3CC = 3 Conductor Cable
B15: I(SC): Available Short-Circuit Current at Beginning of Circuit | J15: PVC = Nonmagnetic
B16: L: Length (ft) of Conductor to the Fault | J16: Stl = Steel
B17: C: Constant from Conductor
B18: n: Number of Conductors per Phase
B19: V: Voltage
B20: Reference: Point-to-Point Calculation Procedure from Short Circtui Calculations, Bussmann by Eaton
B24: Fault (Xformer) | C24: KVA | D24: V | E24: Phase | F24: IFL | G24: %Z | H24: M | I24: I(SC)
B26: 0 | C26: 75 | D26: 230 | E26: 3 | F26: =_xlfn.IFNA(_xlfn.IFS(E26=1, (C26*1000)/D26, E26=3, (C26*1000)/(D26*1.732)), "-") -> 188.27191 | G26: 1.1 | H26: =100/G26 -> 90.909091 | I26: =F26*H26 -> 17115.629
B28: Fault # | C28: Phase | D28: k | E28: L | F28: Ref Fault # | G28: I(SC) Old | H28: Wire Code | I28: Con Dia / Amp | J28: Conductor Type | K28: Conductor Type2 | L28: Conduit Type | M28: Cable Rating | N28: C | O28: n | P28: V | Q28: f | R28: M | S28: I(SC) New | U28: NOTES
B29: 1 | C29: 3 | D29: =IF(COUNTIF($J$5:$J$6, C29)>0, VLOOKUP(Table2[[#This Row],[Phase]], $J$5:$L$6, 3,FALSE), "-") -> 1.732 | E29: 26.24672 | G29: =I26 -> 17115.629 | H29: X8 | I29: =_xlfn.IFNA(VLOOKUP(VLOOKUP(Table2[[#This Row],[Wire Code]], 'Table Reference'!$Z$6:$AA$135, 2, FALSE), 'Table Reference'!$AD$6:$AE$38, 2,FALSE), "-") -> 80 | J29: =_xlfn.IFNA(VLOOKUP(Table2[[#This Row],[Wire Code]], 'Table Reference'!$Z$6:$AB$135, 3, FALSE), "-") -> CU | K29: 3SC | L29: Stl | M29: 600V | N29: =_xlfn.IFNA(IF(OR(Table2[[#This Row],[Conductor Type]]="BUS-CU",Table2[[#This Row],[Conductor Type]]="BUS-AL"), VLOOKUP(Table2[[#This Row],[Con Dia / Amp]], 'Table Reference'!$AH$36:$AK$47, IF(Table2[[#This Row],[Conductor Type]]="BUS-CU", 4, 3)), VLOOKUP(Table2[[#This Row],[Con Dia / Amp]],'Table Reference'!$AH$9:$BI$29,MATCH(Table2[[#This Row],[Conductor Type]] & Table2[[#This Row],[Conductor Type2]] & Table2[[#This Row],[Conduit Type]] & Table2[[#This Row],[Cable Rating]],'Table Reference'!$AH$8:$BI$8,0), FALSE)), "-") -> 12844 | O29: 1 | P29: 230 | Q29: =IFERROR((Table2[[#This Row],[k]]*Table2[[#This Row],[L]]*Table2[[#This Row],[I(SC) Old]])/(Table2[[#This Row],[C]]*Table2[[#This Row],[n]]*Table2[[#This Row],[V]]), "-") -> 0.26338294 | R29: =IFERROR(1/(1+Table2[[#This Row],[f]]), "-") -> 0.79152565 | S29: =IFERROR(_xlfn.IFNA(Table2[[#This Row],[I(SC) Old]]*Table2[[#This Row],[M]], "-"), "-") -> 13547.459 | U29: Transformer to Main Panel
B30: 2 | C30: 1 | D30: =IF(COUNTIF($J$5:$J$6, C30)>0, VLOOKUP(Table2[[#This Row],[Phase]], $J$5:$L$6, 3,FALSE), "-") -> 2 | E30: 59.4488 | F30: 1 | G30: =_xlfn.IFNA(IF(VLOOKUP(Table2[[#This Row],[Ref Fault '#]], Table2[#All], 18,FALSE)>0, VLOOKUP(Table2[[#This Row],[Ref Fault '#]], Table2[#All], 18,FALSE), "-"), "-") -> 13547.459 | H30: W4 | I30: =_xlfn.IFNA(VLOOKUP(VLOOKUP(Table2[[#This Row],[Wire Code]], 'Table Reference'!$Z$6:$AA$135, 2, FALSE), 'Table Reference'!$AD$6:$AE$38, 2,FALSE), "-") -> 22 | J30: =_xlfn.IFNA(VLOOKUP(Table2[[#This Row],[Wire Code]], 'Table Reference'!$Z$6:$AB$135, 3, FALSE), "-") -> CU | K30: 3SC | L30: PVC | M30: 600V | N30: =_xlfn.IFNA(IF(OR(Table2[[#This Row],[Conductor Type]]="BUS-CU",Table2[[#This Row],[Conductor Type]]="BUS-AL"), VLOOKUP(Table2[[#This Row],[Con Dia / Amp]], 'Table Reference'!$AH$36:$AK$47, IF(Table2[[#This Row],[Conductor Type]]="BUS-CU", 4, 3)), VLOOKUP(Table2[[#This Row],[Con Dia / Amp]],'Table Reference'!$AH$9:$BI$29,MATCH(Table2[[#This Row],[Conductor Type]] & Table2[[#This Row],[Conductor Type2]] & Table2[[#This Row],[Conduit Type]] & Table2[[#This Row],[Cable Rating]],'Table Reference'!$AH$8:$BI$8,0), FALSE)), "-") -> 3826 | O30: 1 | P30: 230 | Q30: =IFERROR((Table2[[#This Row],[k]]*Table2[[#This Row],[L]]*Table2[[#This Row],[I(SC) Old]])/(Table2[[#This Row],[C]]*Table2[[#This Row],[n]]*Table2[[#This Row],[V]]), "-") -> 1.8304511 | R30: =IFERROR(1/(1+Table2[[#This Row],[f]]), "-") -> 0.35330057 | S30: =IFERROR(_xlfn.IFNA(Table2[[#This Row],[I(SC) Old]]*Table2[[#This Row],[M]], "-"), "-") -> 4786.325 | U30: Main Panel to PB-2
B31: 3 | C31: 1 | D31: =IF(COUNTIF($J$5:$J$6, C31)>0, VLOOKUP(Table2[[#This Row],[Phase]], $J$5:$L$6, 3,FALSE), "-") -> 2 | E31: 5.9056 | F31: 2 | G31: =_xlfn.IFNA(IF(VLOOKUP(Table2[[#This Row],[Ref Fault '#]], Table2[#All], 18,FALSE)>0, VLOOKUP(Table2[[#This Row],[Ref Fault '#]], Table2[#All], 18,FALSE), "-"), "-") -> 4786.325 | H31: W0 | I31: =_xlfn.IFNA(VLOOKUP(VLOOKUP(Table2[[#This Row],[Wire Code]], 'Table Reference'!$Z$6:$AA$135, 2, FALSE), 'Table Reference'!$AD$6:$AE$38, 2,FALSE), "-") -> 3.5 | J31: =_xlfn.IFNA(VLOOKUP(Table2[[#This Row],[Wire Code]], 'Table Reference'!$Z$6:$AB$135, 3, FALSE), "-") -> CU | K31: 3SC | L31: PVC | M31: 600V | N31: =_xlfn.IFNA(IF(OR(Table2[[#This Row],[Conductor Type]]="BUS-CU",Table2[[#This Row],[Conductor Type]]="BUS-AL"), VLOOKUP(Table2[[#This Row],[Con Dia / Amp]], 'Table Reference'!$AH$36:$AK$47, IF(Table2[[#This Row],[Conductor Type]]="BUS-CU", 4, 3)), VLOOKUP(Table2[[#This Row],[Con Dia / Amp]],'Table Reference'!$AH$9:$BI$29,MATCH(Table2[[#This Row],[Conductor Type]] & Table2[[#This Row],[Conductor Type2]] & Table2[[#This Row],[Conduit Type]] & Table2[[#This Row],[Cable Rating]],'Table Reference'!$AH$8:$BI$8,0), FALSE)), "-") -> 617 | O31: 1 | P31: 230 | Q31: =IFERROR((Table2[[#This Row],[k]]*Table2[[#This Row],[L]]*Table2[[#This Row],[I(SC) Old]])/(Table2[[#This Row],[C]]*Table2[[#This Row],[n]]*Table2[[#This Row],[V]]), "-") -> 0.39836687 | R31: =IFERROR(1/(1+Table2[[#This Row],[f]]), "-") -> 0.71511992 | S31: =IFERROR(_xlfn.IFNA(Table2[[#This Row],[I(SC) Old]]*Table2[[#This Row],[M]], "-"), "-") -> 3422.7964 | U31: pb-2 to nearest outlet
B32: 4 | C32: 1 | D32: =IF(COUNTIF($J$5:$J$6, C32)>0, VLOOKUP(Table2[[#This Row],[Phase]], $J$5:$L$6, 3,FALSE), "-") -> 2 | E32: 78.74 | F32: 1 | G32: =_xlfn.IFNA(IF(VLOOKUP(Table2[[#This Row],[Ref Fault '#]], Table2[#All], 18,FALSE)>0, VLOOKUP(Table2[[#This Row],[Ref Fault '#]], Table2[#All], 18,FALSE), "-"), "-") -> 13547.459 | H32: W3 | I32: =_xlfn.IFNA(VLOOKUP(VLOOKUP(Table2[[#This Row],[Wire Code]], 'Table Reference'!$Z$6:$AA$135, 2, FALSE), 'Table Reference'!$AD$6:$AE$38, 2,FALSE), "-") -> 14 | J32: =_xlfn.IFNA(VLOOKUP(Table2[[#This Row],[Wire Code]], 'Table Reference'!$Z$6:$AB$135, 3, FALSE), "-") -> CU | K32: 3SC | L32: PVC | M32: 600V | N32: =_xlfn.IFNA(IF(OR(Table2[[#This Row],[Conductor Type]]="BUS-CU",Table2[[#This Row],[Conductor Type]]="BUS-AL"), VLOOKUP(Table2[[#This Row],[Con Dia / Amp]], 'Table Reference'!$AH$36:$AK$47, IF(Table2[[#This Row],[Conductor Type]]="BUS-CU", 4, 3)), VLOOKUP(Table2[[#This Row],[Con Dia / Amp]],'Table Reference'!$AH$9:$BI$29,MATCH(Table2[[#This Row],[Conductor Type]] & Table2[[#This Row],[Conductor Type2]] & Table2[[#This Row],[Conduit Type]] & Table2[[#This Row],[Cable Rating]],'Table Reference'!$AH$8:$BI$8,0), FALSE)), "-") -> 2430 | O32: 1 | P32: 230 | Q32: =IFERROR((Table2[[#This Row],[k]]*Table2[[#This Row],[L]]*Table2[[#This Row],[I(SC) Old]])/(Table2[[#This Row],[C]]*Table2[[#This Row],[n]]*Table2[[#This Row],[V]]), "-") -> 3.8172371 | R32: =IFERROR(1/(1+Table2[[#This Row],[f]]), "-") -> 0.20758787 | S32: =IFERROR(_xlfn.IFNA(Table2[[#This Row],[I(SC) Old]]*Table2[[#This Row],[M]], "-"), "-") -> 2812.2882 | U32: main to pb-1
B33: 5 | C33: 1 | D33: =IF(COUNTIF($J$5:$J$6, C33)>0, VLOOKUP(Table2[[#This Row],[Phase]], $J$5:$L$6, 3,FALSE), "-") -> 2 | E33: 7 | F33: 4 | G33: =_xlfn.IFNA(IF(VLOOKUP(Table2[[#This Row],[Ref Fault '#]], Table2[#All], 18,FALSE)>0, VLOOKUP(Table2[[#This Row],[Ref Fault '#]], Table2[#All], 18,FALSE), "-"), "-") -> 2812.2882 | H33: W0 | I33: =_xlfn.IFNA(VLOOKUP(VLOOKUP(Table2[[#This Row],[Wire Code]], 'Table Reference'!$Z$6:$AA$135, 2, FALSE), 'Table Reference'!$AD$6:$AE$38, 2,FALSE), "-") -> 3.5 | J33: =_xlfn.IFNA(VLOOKUP(Table2[[#This Row],[Wire Code]], 'Table Reference'!$Z$6:$AB$135, 3, FALSE), "-") -> CU | K33: 3SC | L33: PVC | M33: 600V | N33: =_xlfn.IFNA(IF(OR(Table2[[#This Row],[Conductor Type]]="BUS-CU",Table2[[#This Row],[Conductor Type]]="BUS-AL"), VLOOKUP(Table2[[#This Row],[Con Dia / Amp]], 'Table Reference'!$AH$36:$AK$47, IF(Table2[[#This Row],[Conductor Type]]="BUS-CU", 4, 3)), VLOOKUP(Table2[[#This Row],[Con Dia / Amp]],'Table Reference'!$AH$9:$BI$29,MATCH(Table2[[#This Row],[Conductor Type]] & Table2[[#This Row],[Conductor Type2]] & Table2[[#This Row],[Conduit Type]] & Table2[[#This Row],[Cable Rating]],'Table Reference'!$AH$8:$BI$8,0), FALSE)), "-") -> 617 | O33: 1 | P33: 230 | Q33: =IFERROR((Table2[[#This Row],[k]]*Table2[[#This Row],[L]]*Table2[[#This Row],[I(SC) Old]])/(Table2[[#This Row],[C]]*Table2[[#This Row],[n]]*Table2[[#This Row],[V]]), "-") -> 0.27744369 | R33: =IFERROR(1/(1+Table2[[#This Row],[f]]), "-") -> 0.78281337 | S33: =IFERROR(_xlfn.IFNA(Table2[[#This Row],[I(SC) Old]]*Table2[[#This Row],[M]], "-"), "-") -> 2201.4968 | U33: pb-1 to nearest outlet
B34: 6 | C34: 1 | D34: =IF(COUNTIF($J$5:$J$6, C34)>0, VLOOKUP(Table2[[#This Row],[Phase]], $J$5:$L$6, 3,FALSE), "-") -> 2 | E34: 95.14 | F34: 1 | G34: =_xlfn.IFNA(IF(VLOOKUP(Table2[[#This Row],[Ref Fault '#]], Table2[#All], 18,FALSE)>0, VLOOKUP(Table2[[#This Row],[Ref Fault '#]], Table2[#All], 18,FALSE), "-"), "-") -> 13547.459 | H34: W0 | I34: =_xlfn.IFNA(VLOOKUP(VLOOKUP(Table2[[#This Row],[Wire Code]], 'Table Reference'!$Z$6:$AA$135, 2, FALSE), 'Table Reference'!$AD$6:$AE$38, 2,FALSE), "-") -> 3.5 | J34: =_xlfn.IFNA(VLOOKUP(Table2[[#This Row],[Wire Code]], 'Table Reference'!$Z$6:$AB$135, 3, FALSE), "-") -> CU | K34: 3SC | L34: PVC | M34: 600V | N34: =_xlfn.IFNA(IF(OR(Table2[[#This Row],[Conductor Type]]="BUS-CU",Table2[[#This Row],[Conductor Type]]="BUS-AL"), VLOOKUP(Table2[[#This Row],[Con Dia / Amp]], 'Table Reference'!$AH$36:$AK$47, IF(Table2[[#This Row],[Conductor Type]]="BUS-CU", 4, 3)), VLOOKUP(Table2[[#This Row],[Con Dia / Amp]],'Table Reference'!$AH$9:$BI$29,MATCH(Table2[[#This Row],[Conductor Type]] & Table2[[#This Row],[Conductor Type2]] & Table2[[#This Row],[Conduit Type]] & Table2[[#This Row],[Cable Rating]],'Table Reference'!$AH$8:$BI$8,0), FALSE)), "-") -> 617 | O34: 1 | P34: 230 | Q34: =IFERROR((Table2[[#This Row],[k]]*Table2[[#This Row],[L]]*Table2[[#This Row],[I(SC) Old]])/(Table2[[#This Row],[C]]*Table2[[#This Row],[n]]*Table2[[#This Row],[V]]), "-") -> 18.165108 | R34: =IFERROR(1/(1+Table2[[#This Row],[f]]), "-") -> 0.052178156 | S34: =IFERROR(_xlfn.IFNA(Table2[[#This Row],[I(SC) Old]]*Table2[[#This Row],[M]], "-"), "-") -> 706.88143
B35: 7 | D35: =IF(COUNTIF($J$5:$J$6, C35)>0, VLOOKUP(Table2[[#This Row],[Phase]], $J$5:$L$6, 3,FALSE), "-") -> - | G35: =_xlfn.IFNA(IF(VLOOKUP(Table2[[#This Row],[Ref Fault '#]], Table2[#All], 18,FALSE)>0, VLOOKUP(Table2[[#This Row],[Ref Fault '#]], Table2[#All], 18,FALSE), "-"), "-") -> - | I35: =_xlfn.IFNA(VLOOKUP(VLOOKUP(Table2[[#This Row],[Wire Code]], 'Table Reference'!$Z$6:$AA$135, 2, FALSE), 'Table Reference'!$AD$6:$AE$38, 2,FALSE), "-") -> - | J35: =_xlfn.IFNA(VLOOKUP(Table2[[#This Row],[Wire Code]], 'Table Reference'!$Z$6:$AB$135, 3, FALSE), "-") -> - | N35: =_xlfn.IFNA(IF(OR(Table2[[#This Row],[Conductor Type]]="BUS-CU",Table2[[#This Row],[Conductor Type]]="BUS-AL"), VLOOKUP(Table2[[#This Row],[Con Dia / Amp]], 'Table Reference'!$AH$36:$AK$47, IF(Table2[[#This Row],[Conductor Type]]="BUS-CU", 4, 3)), VLOOKUP(Table2[[#This Row],[Con Dia / Amp]],'Table Reference'!$AH$9:$BI$29,MATCH(Table2[[#This Row],[Conductor Type]] & Table2[[#This Row],[Conductor Type2]] & Table2[[#This Row],[Conduit Type]] & Table2[[#This Row],[Cable Rating]],'Table Reference'!$AH$8:$BI$8,0), FALSE)), "-") -> - | Q35: =IFERROR((Table2[[#This Row],[k]]*Table2[[#This Row],[L]]*Table2[[#This Row],[I(SC) Old]])/(Table2[[#This Row],[C]]*Table2[[#This Row],[n]]*Table2[[#This Row],[V]]), "-") -> - | R35: =IFERROR(1/(1+Table2[[#This Row],[f]]), "-") -> - | S35: =IFERROR(_xlfn.IFNA(Table2[[#This Row],[I(SC) Old]]*Table2[[#This Row],[M]], "-"), "-") -> -
B36: 8 | D36: =IF(COUNTIF($J$5:$J$6, C36)>0, VLOOKUP(Table2[[#This Row],[Phase]], $J$5:$L$6, 3,FALSE), "-") -> - | G36: =_xlfn.IFNA(IF(VLOOKUP(Table2[[#This Row],[Ref Fault '#]], Table2[#All], 18,FALSE)>0, VLOOKUP(Table2[[#This Row],[Ref Fault '#]], Table2[#All], 18,FALSE), "-"), "-") -> - | I36: =_xlfn.IFNA(VLOOKUP(VLOOKUP(Table2[[#This Row],[Wire Code]], 'Table Reference'!$Z$6:$AA$135, 2, FALSE), 'Table Reference'!$AD$6:$AE$38, 2,FALSE), "-") -> - | J36: =_xlfn.IFNA(VLOOKUP(Table2[[#This Row],[Wire Code]], 'Table Reference'!$Z$6:$AB$135, 3, FALSE), "-") -> - | N36: =_xlfn.IFNA(IF(OR(Table2[[#This Row],[Conductor Type]]="BUS-CU",Table2[[#This Row],[Conductor Type]]="BUS-AL"), VLOOKUP(Table2[[#This Row],[Con Dia / Amp]], 'Table Reference'!$AH$36:$AK$47, IF(Table2[[#This Row],[Conductor Type]]="BUS-CU", 4, 3)), VLOOKUP(Table2[[#This Row],[Con Dia / Amp]],'Table Reference'!$AH$9:$BI$29,MATCH(Table2[[#This Row],[Conductor Type]] & Table2[[#This Row],[Conductor Type2]] & Table2[[#This Row],[Conduit Type]] & Table2[[#This Row],[Cable Rating]],'Table Reference'!$AH$8:$BI$8,0), FALSE)), "-") -> - | Q36: =IFERROR((Table2[[#This Row],[k]]*Table2[[#This Row],[L]]*Table2[[#This Row],[I(SC) Old]])/(Table2[[#This Row],[C]]*Table2[[#This Row],[n]]*Table2[[#This Row],[V]]), "-") -> - | R36: =IFERROR(1/(1+Table2[[#This Row],[f]]), "-") -> - | S36: =IFERROR(_xlfn.IFNA(Table2[[#This Row],[I(SC) Old]]*Table2[[#This Row],[M]], "-"), "-") -> -
B37: 9 | D37: =IF(COUNTIF($J$5:$J$6, C37)>0, VLOOKUP(Table2[[#This Row],[Phase]], $J$5:$L$6, 3,FALSE), "-") -> - | G37: =_xlfn.IFNA(IF(VLOOKUP(Table2[[#This Row],[Ref Fault '#]], Table2[#All], 18,FALSE)>0, VLOOKUP(Table2[[#This Row],[Ref Fault '#]], Table2[#All], 18,FALSE), "-"), "-") -> - | I37: =_xlfn.IFNA(VLOOKUP(VLOOKUP(Table2[[#This Row],[Wire Code]], 'Table Reference'!$Z$6:$AA$135, 2, FALSE), 'Table Reference'!$AD$6:$AE$38, 2,FALSE), "-") -> - | J37: =_xlfn.IFNA(VLOOKUP(Table2[[#This Row],[Wire Code]], 'Table Reference'!$Z$6:$AB$135, 3, FALSE), "-") -> - | N37: =_xlfn.IFNA(IF(OR(Table2[[#This Row],[Conductor Type]]="BUS-CU",Table2[[#This Row],[Conductor Type]]="BUS-AL"), VLOOKUP(Table2[[#This Row],[Con Dia / Amp]], 'Table Reference'!$AH$36:$AK$47, IF(Table2[[#This Row],[Conductor Type]]="BUS-CU", 4, 3)), VLOOKUP(Table2[[#This Row],[Con Dia / Amp]],'Table Reference'!$AH$9:$BI$29,MATCH(Table2[[#This Row],[Conductor Type]] & Table2[[#This Row],[Conductor Type2]] & Table2[[#This Row],[Conduit Type]] & Table2[[#This Row],[Cable Rating]],'Table Reference'!$AH$8:$BI$8,0), FALSE)), "-") -> - | Q37: =IFERROR((Table2[[#This Row],[k]]*Table2[[#This Row],[L]]*Table2[[#This Row],[I(SC) Old]])/(Table2[[#This Row],[C]]*Table2[[#This Row],[n]]*Table2[[#This Row],[V]]), "-") -> - | R37: =IFERROR(1/(1+Table2[[#This Row],[f]]), "-") -> - | S37: =IFERROR(_xlfn.IFNA(Table2[[#This Row],[I(SC) Old]]*Table2[[#This Row],[M]], "-"), "-") -> -
B38: 10 | D38: =IF(COUNTIF($J$5:$J$6, C38)>0, VLOOKUP(Table2[[#This Row],[Phase]], $J$5:$L$6, 3,FALSE), "-") -> - | G38: =_xlfn.IFNA(IF(VLOOKUP(Table2[[#This Row],[Ref Fault '#]], Table2[#All], 18,FALSE)>0, VLOOKUP(Table2[[#This Row],[Ref Fault '#]], Table2[#All], 18,FALSE), "-"), "-") -> - | I38: =_xlfn.IFNA(VLOOKUP(VLOOKUP(Table2[[#This Row],[Wire Code]], 'Table Reference'!$Z$6:$AA$135, 2, FALSE), 'Table Reference'!$AD$6:$AE$38, 2,FALSE), "-") -> - | J38: =_xlfn.IFNA(VLOOKUP(Table2[[#This Row],[Wire Code]], 'Table Reference'!$Z$6:$AB$135, 3, FALSE), "-") -> - | N38: =_xlfn.IFNA(IF(OR(Table2[[#This Row],[Conductor Type]]="BUS-CU",Table2[[#This Row],[Conductor Type]]="BUS-AL"), VLOOKUP(Table2[[#This Row],[Con Dia / Amp]], 'Table Reference'!$AH$36:$AK$47, IF(Table2[[#This Row],[Conductor Type]]="BUS-CU", 4, 3)), VLOOKUP(Table2[[#This Row],[Con Dia / Amp]],'Table Reference'!$AH$9:$BI$29,MATCH(Table2[[#This Row],[Conductor Type]] & Table2[[#This Row],[Conductor Type2]] & Table2[[#This Row],[Conduit Type]] & Table2[[#This Row],[Cable Rating]],'Table Reference'!$AH$8:$BI$8,0), FALSE)), "-") -> - | Q38: =IFERROR((Table2[[#This Row],[k]]*Table2[[#This Row],[L]]*Table2[[#This Row],[I(SC) Old]])/(Table2[[#This Row],[C]]*Table2[[#This Row],[n]]*Table2[[#This Row],[V]]), "-") -> - | R38: =IFERROR(1/(1+Table2[[#This Row],[f]]), "-") -> - | S38: =IFERROR(_xlfn.IFNA(Table2[[#This Row],[I(SC) Old]]*Table2[[#This Row],[M]], "-"), "-") -> -
B39: 12 | D39: =IF(COUNTIF($J$5:$J$6, C39)>0, VLOOKUP(Table2[[#This Row],[Phase]], $J$5:$L$6, 3,FALSE), "-") -> - | G39: =_xlfn.IFNA(IF(VLOOKUP(Table2[[#This Row],[Ref Fault '#]], Table2[#All], 18,FALSE)>0, VLOOKUP(Table2[[#This Row],[Ref Fault '#]], Table2[#All], 18,FALSE), "-"), "-") -> - | I39: =_xlfn.IFNA(VLOOKUP(VLOOKUP(Table2[[#This Row],[Wire Code]], 'Table Reference'!$Z$6:$AA$135, 2, FALSE), 'Table Reference'!$AD$6:$AE$38, 2,FALSE), "-") -> - | J39: =_xlfn.IFNA(VLOOKUP(Table2[[#This Row],[Wire Code]], 'Table Reference'!$Z$6:$AB$135, 3, FALSE), "-") -> - | N39: =_xlfn.IFNA(IF(OR(Table2[[#This Row],[Conductor Type]]="BUS-CU",Table2[[#This Row],[Conductor Type]]="BUS-AL"), VLOOKUP(Table2[[#This Row],[Con Dia / Amp]], 'Table Reference'!$AH$36:$AK$47, IF(Table2[[#This Row],[Conductor Type]]="BUS-CU", 4, 3)), VLOOKUP(Table2[[#This Row],[Con Dia / Amp]],'Table Reference'!$AH$9:$BI$29,MATCH(Table2[[#This Row],[Conductor Type]] & Table2[[#This Row],[Conductor Type2]] & Table2[[#This Row],[Conduit Type]] & Table2[[#This Row],[Cable Rating]],'Table Reference'!$AH$8:$BI$8,0), FALSE)), "-") -> - | Q39: =IFERROR((Table2[[#This Row],[k]]*Table2[[#This Row],[L]]*Table2[[#This Row],[I(SC) Old]])/(Table2[[#This Row],[C]]*Table2[[#This Row],[n]]*Table2[[#This Row],[V]]), "-") -> - | R39: =IFERROR(1/(1+Table2[[#This Row],[f]]), "-") -> - | S39: =IFERROR(_xlfn.IFNA(Table2[[#This Row],[I(SC) Old]]*Table2[[#This Row],[M]], "-"), "-") -> -
B40: 13 | D40: =IF(COUNTIF($J$5:$J$6, C40)>0, VLOOKUP(Table2[[#This Row],[Phase]], $J$5:$L$6, 3,FALSE), "-") -> - | G40: =_xlfn.IFNA(IF(VLOOKUP(Table2[[#This Row],[Ref Fault '#]], Table2[#All], 18,FALSE)>0, VLOOKUP(Table2[[#This Row],[Ref Fault '#]], Table2[#All], 18,FALSE), "-"), "-") -> - | I40: =_xlfn.IFNA(VLOOKUP(VLOOKUP(Table2[[#This Row],[Wire Code]], 'Table Reference'!$Z$6:$AA$135, 2, FALSE), 'Table Reference'!$AD$6:$AE$38, 2,FALSE), "-") -> - | J40: =_xlfn.IFNA(VLOOKUP(Table2[[#This Row],[Wire Code]], 'Table Reference'!$Z$6:$AB$135, 3, FALSE), "-") -> - | N40: =_xlfn.IFNA(IF(OR(Table2[[#This Row],[Conductor Type]]="BUS-CU",Table2[[#This Row],[Conductor Type]]="BUS-AL"), VLOOKUP(Table2[[#This Row],[Con Dia / Amp]], 'Table Reference'!$AH$36:$AK$47, IF(Table2[[#This Row],[Conductor Type]]="BUS-CU", 4, 3)), VLOOKUP(Table2[[#This Row],[Con Dia / Amp]],'Table Reference'!$AH$9:$BI$29,MATCH(Table2[[#This Row],[Conductor Type]] & Table2[[#This Row],[Conductor Type2]] & Table2[[#This Row],[Conduit Type]] & Table2[[#This Row],[Cable Rating]],'Table Reference'!$AH$8:$BI$8,0), FALSE)), "-") -> - | Q40: =IFERROR((Table2[[#This Row],[k]]*Table2[[#This Row],[L]]*Table2[[#This Row],[I(SC) Old]])/(Table2[[#This Row],[C]]*Table2[[#This Row],[n]]*Table2[[#This Row],[V]]), "-") -> - | R40: =IFERROR(1/(1+Table2[[#This Row],[f]]), "-") -> - | S40: =IFERROR(_xlfn.IFNA(Table2[[#This Row],[I(SC) Old]]*Table2[[#This Row],[M]], "-"), "-") -> -
